Workbook

Sheet metadata
A1: Note: all this data was copied from "EAB_Michigan_2024_raw_data_photos_removed.xlsx" and then reorganized for better understanding
A4: microplot observations
A5: mstrlvl
A6: pltmstr
A7: center_tree_number
A8: percent_cover_0_0.5_1_3.5_8_15.5_25.5_etc | B8: percent cover in that microplot of ash seedlings (anything below 137 cm tall)
A9: ash_seedlings_notes | B9: notes on the microplot - generally what type of ground cover, and some (not all) of the understory plants found there
A11: plot observations
A12: center_tree_number
A13: mstrlvl
A14: plotmstr
A15: Park
A16: ash_plot_centers_notes_2024 | B16: notes on some (not all) of the tree species found at each plot, along with some other info on ash trees there
A17: Center_tree_updated_2024 | B17: info on the center tree, collected in 2024

Sheet microplot observations
A1: mstrlvl | B1: pltmstr | C1: center_tree_number | D1: percent_cover_0_0.5_1_3.5_8_15.5_25.5_etc | E1: ash_seedlings_notes
A2: =VLOOKUP(C2, Sheet2!$A$1:$C$130, 2, TRUE) -> xeric | B2: =VLOOKUP(C2, Sheet2!$A$1:$C$130, 3, TRUE) -> 1 | C2: 1 | D2: 3.5
A3: =VLOOKUP(C3, Sheet2!$A$1:$C$130, 2, TRUE) -> xeric | B3: =VLOOKUP(C3, Sheet2!$A$1:$C$130, 3, TRUE) -> 1 | C3: 1 | D3: 3.5
A4: =VLOOKUP(C4, Sheet2!$A$1:$C$130, 2, TRUE) -> xeric | B4: =VLOOKUP(C4, Sheet2!$A$1:$C$130, 3, TRUE) -> 1 | C4: 1 | D4: 15.5
A5: =VLOOKUP(C5, Sheet2!$A$1:$C$130, 2, TRUE) -> xeric | B5: =VLOOKUP(C5, Sheet2!$A$1:$C$130, 3, TRUE) -> 1 | C5: 1 | D5: 3.5
A6: =VLOOKUP(C6, Sheet2!$A$1:$C$130, 2, TRUE) -> xeric | B6: =VLOOKUP(C6, Sheet2!$A$1:$C$130, 3, TRUE) -> 1 | C6: 2 | D6: 3.5
A7: =VLOOKUP(C7, Sheet2!$A$1:$C$130, 2, TRUE) -> xeric | B7: =VLOOKUP(C7, Sheet2!$A$1:$C$130, 3, TRUE) -> 1 | C7: 2 | D7: 3.5
A8: =VLOOKUP(C8, Sheet2!$A$1:$C$130, 2, TRUE) -> xeric | B8: =VLOOKUP(C8, Sheet2!$A$1:$C$130, 3, TRUE) -> 1 | C8: 2 | D8: 0
A9: =VLOOKUP(C9, Sheet2!$A$1:$C$130, 2, TRUE) -> xeric | B9: =VLOOKUP(C9, Sheet2!$A$1:$C$130, 3, TRUE) -> 1 | C9: 2 | D9: 8 | E9: In NW - there is an approx. 2m tall ash just outside the microplot.
A10: =VLOOKUP(C10, Sheet2!$A$1:$C$130, 2, TRUE) -> xeric | B10: =VLOOKUP(C10, Sheet2!$A$1:$C$130, 3, TRUE) -> 1 | C10: 3 | D10: 0
A11: =VLOOKUP(C11, Sheet2!$A$1:$C$130, 2, TRUE) -> xeric | B11: =VLOOKUP(C11, Sheet2!$A$1:$C$130, 3, TRUE) -> 1 | C11: 3 | D11: 0 | E11: 1m north of a fork of fallen elm (2nd fork on left).
A12: =VLOOKUP(C12, Sheet2!$A$1:$C$130, 2, TRUE) -> xeric | B12: =VLOOKUP(C12, Sheet2!$A$1:$C$130, 3, TRUE) -> 1 | C12: 3 | D12: 0 | E12: Just .5m east of autum olive.
A13: =VLOOKUP(C13, Sheet2!$A$1:$C$130, 2, TRUE) -> xeric | B13: =VLOOKUP(C13, Sheet2!$A$1:$C$130, 3, TRUE) -> 1 | C13: 3 | D13: 0
A14: =VLOOKUP(C14, Sheet2!$A$1:$C$130, 2, TRUE) -> xeric | B14: =VLOOKUP(C14, Sheet2!$A$1:$C$130, 3, TRUE) -> 1 | C14: 7 | D14: 0 | E14: fallen leaves
A15: =VLOOKUP(C15, Sheet2!$A$1:$C$130, 2, TRUE) -> xeric | B15: =VLOOKUP(C15, Sheet2!$A$1:$C$130, 3, TRUE) -> 1 | C15: 7 | D15: 8 | E15: fallen leaves - short grasses
A16: =VLOOKUP(C16, Sheet2!$A$1:$C$130, 2, TRUE) -> xeric | B16: =VLOOKUP(C16, Sheet2!$A$1:$C$130, 3, TRUE) -> 1 | C16: 7 | D16: 8 | E16: fallen leaves- short grasses
A17: =VLOOKUP(C17, Sheet2!$A$1:$C$130, 2, TRUE) -> xeric | B17: =VLOOKUP(C17, Sheet2!$A$1:$C$130, 3, TRUE) -> 1 | C17: 7 | D17: 3.5 | E17: fallen leaves - short grasses
A18: =VLOOKUP(C18, Sheet2!$A$1:$C$130, 2, TRUE) -> xeric | B18: =VLOOKUP(C18, Sheet2!$A$1:$C$130, 3, TRUE) -> 1 | C18: 8 | D18: 3.5 | E18: tall grasses - fallen leaves
A19: =VLOOKUP(C19, Sheet2!$A$1:$C$130, 2, TRUE) -> xeric | B19: =VLOOKUP(C19, Sheet2!$A$1:$C$130, 3, TRUE) -> 1 | C19: 8 | D19: 0 | E19: fallen leaves
A20: =VLOOKUP(C20, Sheet2!$A$1:$C$130, 2, TRUE) -> xeric | B20: =VLOOKUP(C20, Sheet2!$A$1:$C$130, 3, TRUE) -> 1 | C20: 8 | D20: 0 | E20: fallen leaves
A21: =VLOOKUP(C21, Sheet2!$A$1:$C$130, 2, TRUE) -> xeric | B21: =VLOOKUP(C21, Sheet2!$A$1:$C$130, 3, TRUE) -> 1 | C21: 8 | D21: 3.5 | E21: American jumpseed - fallen leaves
A22: =VLOOKUP(C22, Sheet2!$A$1:$C$130, 2, TRUE) -> xeric | B22: =VLOOKUP(C22, Sheet2!$A$1:$C$130, 3, TRUE) -> 1 | C22: 9 | D22: 3.5 | E22: fallen leaves - herbicides maybe being used on invasives here
A23: =VLOOKUP(C23, Sheet2!$A$1:$C$130, 2, TRUE) -> xeric | B23: =VLOOKUP(C23, Sheet2!$A$1:$C$130, 3, TRUE) -> 1 | C23: 9 | D23: 0 | E23: fallen leaves
A24: =VLOOKUP(C24, Sheet2!$A$1:$C$130, 2, TRUE) -> xeric | B24: =VLOOKUP(C24, Sheet2!$A$1:$C$130, 3, TRUE) -> 1 | C24: 9 | D24: 1 | E24: fallen leaves - short grasses - tall grasses
A25: =VLOOKUP(C25, Sheet2!$A$1:$C$130, 2, TRUE) -> xeric | B25: =VLOOKUP(C25, Sheet2!$A$1:$C$130, 3, TRUE) -> 1 | C25: 9 | D25: 3.5 | E25: beech seedling - fallen leaves
... A36: =VLOOKUP(C36, Sheet2!$A$1:$C$130, 2, TRUE) -> xeric | B36: =VLOOKUP(C36, Sheet2!$A$1:$C$130, 3, TRUE) -> 1 | C36: 14 | D36: 8 | E36: short grasses - may apple
A37: =VLOOKUP(C37, Sheet2!$A$1:$C$130, 2, TRUE) -> xeric | B37: =VLOOKUP(C37, Sheet2!$A$1:$C$130, 3, TRUE) -> 1 | C37: 14 | D37: 35.5
A38: =VLOOKUP(C38, Sheet2!$A$1:$C$130, 2, TRUE) -> xeric | B38: =VLOOKUP(C38, Sheet2!$A$1:$C$130, 3, TRUE) -> 1 | C38: 15 | D38: 8 | E38: may apple - fallen leaves - Celastrus
A39: =VLOOKUP(C39, Sheet2!$A$1:$C$130, 2, TRUE) -> xeric | B39: =VLOOKUP(C39, Sheet2!$A$1:$C$130, 3, TRUE) -> 1 | C39: 15 | D39: 3.5 | E39: galls on ash - fallen leaves
A40: =VLOOKUP(C40, Sheet2!$A$1:$C$130, 2, TRUE) -> xeric | B40: =VLOOKUP(C40, Sheet2!$A$1:$C$130, 3, TRUE) -> 1 | C40: 15 | D40: 3.5 | E40: fallen leaves
A41: =VLOOKUP(C41, Sheet2!$A$1:$C$130, 2, TRUE) -> xeric | B41: =VLOOKUP(C41, Sheet2!$A$1:$C$130, 3, TRUE) -> 1 | C41: 15 | D41: 0 | E41: fallen leaves
A42: =VLOOKUP(C42, Sheet2!$A$1:$C$130, 2, TRUE) -> xeric | B42: =VLOOKUP(C42, Sheet2!$A$1:$C$130, 3, TRUE) -> 1 | C42: 19 | D42: 1 | E42: fallen leaves
A43: =VLOOKUP(C43, Sheet2!$A$1:$C$130, 2, TRUE) -> xeric | B43: =VLOOKUP(C43, Sheet2!$A$1:$C$130, 3, TRUE) -> 1 | C43: 19 | D43: 1 | E43: fallen leaves - galls on ash
A44: =VLOOKUP(C44, Sheet2!$A$1:$C$130, 2, TRUE) -> xeric | B44: =VLOOKUP(C44, Sheet2!$A$1:$C$130, 3, TRUE) -> 1 | C44: 19 | D44: 0 | E44: fallen leaves
A45: =VLOOKUP(C45, Sheet2!$A$1:$C$130, 2, TRUE) -> xeric | B45: =VLOOKUP(C45, Sheet2!$A$1:$C$130, 3, TRUE) -> 1 | C45: 19 | D45: 8 | E45: one ash seedling with dying leaves
A46: =VLOOKUP(C46, Sheet2!$A$1:$C$130, 2, TRUE) -> xeric | B46: =VLOOKUP(C46, Sheet2!$A$1:$C$130, 3, TRUE) -> 1 | C46: 20 | D46: 0.5 | E46: American jumpseed - Arabidopsis thing
A47: =VLOOKUP(C47, Sheet2!$A$1:$C$130, 2, TRUE) -> xeric | B47: =VLOOKUP(C47, Sheet2!$A$1:$C$130, 3, TRUE) -> 1 | C47: 20 | D47: 1 | E47: American jumpseed - Arabidopsis thing
A48: =VLOOKUP(C48, Sheet2!$A$1:$C$130, 2, TRUE) -> xeric | B48: =VLOOKUP(C48, Sheet2!$A$1:$C$130, 3, TRUE) -> 1 | C48: 20 | D48: 1 | E48: fallen leaves
A49: =VLOOKUP(C49, Sheet2!$A$1:$C$130, 2, TRUE) -> xeric | B49: =VLOOKUP(C49, Sheet2!$A$1:$C$130, 3, TRUE) -> 1 | C49: 20 | D49: 0 | E49: fallen leaves
... A53: =VLOOKUP(C53, Sheet2!$A$1:$C$130, 2, TRUE) -> xeric | B53: =VLOOKUP(C53, Sheet2!$A$1:$C$130, 3, TRUE) -> 1 | C53: 21 | D53: 0 | E53: fallen leaves
...

Sheet plot observations
A1: center_tree_number | B1: mstrlvl | C1: plotmstr | D1: Park | E1: ash_plot_centers_notes_2024 | F1: Center_tree_updated_2024
A2: 1 | B2: xeric | C2: 1 | D2: Kensington | F2: 23.2 cm black cherry
A3: 2 | B3: xeric | C3: 1 | D3: Kensington | F3: 11.25 cm choke cherry
A4: 3 | B4: xeric | C4: 1 | D4: Kensington | F4: Center tree down - stump remains - PVC placed on S side.
A5: 7 | B5: xeric | C5: 1 | D5: Kensington | E5: basswoods - big oaks - hickories - beech - elm (slippery??) | F5: 18.6 cm Carya
A6: 8 | B6: xeric | C6: 1 | D6: Kensington | E6: Serviceberry - hawthorn - hickory - white oak - red oak - elm | F6: 36.7 + 12.8 cm Carya spp - tree tag partly swallowed
A7: 9 | B7: xeric | C7: 1 | D7: Kensington | E7: Red oak - cherry - walnut - hickory - red maple - white oak - beech | F7: 16.1 cm Quercus alba
A8: 12 | B8: xeric | C8: 1 | D8: Hudson Mills | E8: Possibly serviceberry (see photos). Understory with American jumpseed. Red oaks - bigger Ostrya - cherry - hickory- white oak - some (few) Tilia. | F8: 32.8 cm Prunus
A9: 13 | B9: xeric | C9: 1 | D9: Kensington | E9: very few ash - big red oaks - cherries - white oaks - Ostrya - Crataegus - hickory - some red maples - beech | F9: 25.9 cm - 1 trunk
A10: 14 | B10: xeric | C10: 1 | D10: Kensington | E10: Serviceberry - red oak - white oak - hickory - cherry - red maple | F10: 10.9 cm Amelanchier
A11: 15 | B11: xeric | C11: 1 | D11: Kensington | E11: Ostrya - red oaks - cherry - 1 bigtooth aspen - dogwood - hickory. Understory sparse - some honeysuckle and Celastrus. | F11: 9.8 cm Ostrya
A12: 19 | B12: xeric | C12: 1 | D12: Kensington | E12: Sunnier spots covered with an Arabidopsis-type plant and American jumpseed. Black oak (?)(leaves with wider lobes) - walnut - sassafrass - white oak - cherry - elm - maple spp | F12: 33.0 cm Acer spp,
A13: 20 | B13: xeric | C13: 1 | D13: Kensington | E13: Cottonwood - walnut - hickory - slippery elm - cherry - oak (post oak??) | F13: 25.2 cm cherry
A14: 21 | B14: xeric | C14: 1 | D14: Kensington | E14: Lots of red or black oak - cherry - beech - sassafrass. Some red maple - slippery elm - hickory | F14: Center tree down
A15: 26 | B15: xeric | C15: 1 | D15: Proud Lake | F15: 13.7 cm Quercus
A16: 27 | B16: xeric | C16: 1 | D16: Proud Lake | F16: 22.8 cm Prunus serotina
A17: 29 | B17: xeric | C17: 1 | D17: Highland | E17: Lots of sugar maple - beech - Ostrya - smooth barked hickory - maybe a tuliptree | F17: 48.5 cm Acer saccharum - tree tag missing - only 1 microplot PVC found - no rebar found - map and GARMIN match the tree we found
A18: 30 | B18: xeric | C18: 1 | D18: Highland | E18: Tuliptree - hickory (smooth and shaggy barked) - red oak - LOTS of maple (sugar?) - Ostrya | F18: 48.1 cm Quercus (red or black oak) - tree tag almost swallowed
A19: 31 | B19: xeric | C19: 1 | D19: Proud Lake | F19: 16.2 cm Acer rubrum - tree tag mostly swallowed
A20: 33 | B20: xeric | C20: 1 | D20: Proud Lake | F20: Prunus serotina 19.9 cm - tree tag missing
A21: 34 | B21: xeric | C21: 1 | D21: Proud Lake | E21: dominant species maple beech and some pine | F21: Acer rubrum 2-stem 5.4 + 4.3 cm
A22: 35 | B22: xeric | C22: 1 | D22: Proud Lake | E22: dominant species maple and beech | F22: Acer 25.5 cm + 18.5 cm + 11.5 cm 3-stem
A23: 36 | B23: xeric | C23: 1 | D23: Proud Lake | F23: 23.6 cm black oak
A24: 53 | B24: mesic | C24: 1 | D24: Pontiac Lake | E24: a lot of vine pressure at this site - vines are competing with ash trees | F24: Q. rubra 28.1 cm
A25: 58 | B25: xeric | C25: 1 | D25: Pontiac Lake | F25: 34.5 cm Quercus (red oak group) - tree tag partly swallowed
A26: 59 | B26: xeric | C26: 1 | D26: Pontiac Lake | E26: Bigger witchhazels in the understory - tulip poplar - Populus - red oak - Tilia - Acer - wingstem in understory | F26: 24.7 cm at DBH (2 fused trunks)
A27: 60 | B27: xeric | C27: 1 | D27: Pontiac Lake | E27: Red oak - red maple - hickory (mockernut?, shagbark?) - dogwood (alternate leaved?) - white oak - cherry (choke cherry?) - sassafrass - viburnum in understory | F27: 29.9 cm hickory
A28: 85 | B28: mesic | C28: 1 | D28: Highland | E28: White oak - sugar maple - Populus (bigtooth aspen?) - cherry - swamp white oak (?) - red oak - beech - white oak - swampy part has an interesting sedge (see photo) | F28: We cannot find the center tree. We found 2 microplots as well as a depression where a tree once was. The North and West microplots were replaced.
A29: 88 | B29: xeric | C29: 1 | D29: Highland | E29: A slightly open area in the East is filled with Desmodium (tick-trefoil) and a mystery herbaceous plant (see photo). Dogwoods are doing well in the open areas. Most of the plot has large oaks (likely red oak)(see acorn photo)(leaf litter is dominated by red oak) - some red maple | F29: 21.9 cm Acer spp.
A30: 89 | B30: xeric | C30: 1 | D30: Highland | E30: White oaks - hickories - red maple - Sassafras - red or black oak - Ostrya. Wet part to the South has cattail - poison sumac. | F30: 54.4 cm Quercus alba
A31: 90 | B31: xeric | C31: 1 | D31: Highland | E31: Black oak - Ostrya - white oak - hickories - beech - cherry | F31: 25.6 cm beech - tree tag partly swallowed
A32: 93 | B32: xeric | C32: 1 | D32: Hudson Mills
A33: 101 | B33: xeric | C33: 1 | D33: Pontiac Lake | E33: Populus - Acer - white oak - hickory - sassafrass - Prunus understory - Tilia | F33: 24.0 cm Acer rubrum
A34: 112 | B34: xeric | C34: 1 | D34: Kensington | F34: Center tree down. Center tree does have PVC and metal stake.
A35: 113 | B35: xeric | C35: 1 | D35: Kensington | E35: North and West microplots are in the equestrian path - those PVCs were not placed | F35: 57.3 cm DBH Walnut
A36: 114 | B36: xeric | C36: 1 | D36: Kensington | F36: 96 cm Walnut
A37: 10 | B37: xeric | C37: 2 | D37: Hudson Mills | E37: Bigtooth aspen - bitternut (and other Carya (?)) - walnut - some smaller Tilia - an elm - Prunus (choke?) | F37: 40.6 cm Quercus (red oak group) - tag missing
A38: 11 | B38: xeric | C38: 2 | D38: Hudson Mills | E38: Cherry - elm - Tilia (lots) - Ostrya - hickory - white and red oak - Sassafrass - sugar maple. Some ash small trees in the 8-18 m or just outside it. | F38: Tree down - missing. Rebar intact.
A39: 16 | B39: mesic | C39: 2 | D39: Island Lake | E39: Tilia - bitternut hickory - sugar maple - beech - red oak - serviceberry or musclewood (see photo) - Ostrya - cottonwood (? See photo) | F39: 57.6 cm Acer saccharum - tree tag mostly swallowed
A40: 32 | B40: xeric | C40: 2 | D40: Proud Lake | F40: 43 cm + 19.7 cm Prunus 2-stem - tree tag missing
...

Sheet Sheet2
A1: center_tree_number | B1: mstrlvl | C1: plotmstr
A2: 1 | B2: xeric | C2: 1
A3: 2 | B3: xeric | C3: 1
A4: 3 | B4: xeric | C4: 1
A5: 4 | B5: mesic | C5: 3
A6: 5 | B6: mesic | C6: 3
A7: 6 | B7: mesic | C7: 3
A8: 7 | B8: xeric | C8: 1
A9: 8 | B9: xeric | C9: 1
A10: 9 | B10: xeric | C10: 1
A11: 10 | B11: xeric | C11: 2
A12: 11 | B12: xeric | C12: 2
A13: 12 | B13: xeric | C13: 1
... A130: 129 | B130: xeric | C130: 1
